Workbook
Name EvM_em: #REF!
Name EvM_eva: #REF!
Name PEI: #REF!

Sheet Monitor
A1: año | B1: mes | C1: fecha | D1: fecha_reg | E1: saldo_total (miles de $) | F1: saldo_irregular (miles de $) | G1: tasa_mora | H1: Sector_1_dígito | I1: id | J1: Nombre
A2: =LEFT(D2,4) -> 2024 | B2: =RIGHT(D2,2) -> 02 | C2: =DATE(A2,B2,1) -> 45323 | D2: 202402 | E2: 1453023432 | F2: 20365428 | G2: =F2/E2 -> 0.014015898 | H2: Agricultura, ganadería y silvicultura | I2: 11 | J2: Cultivos temporales
A3: =LEFT(D3,4) -> 2024 | B3: =RIGHT(D3,2) -> 02 | C3: =DATE(A3,B3,1) -> 45323 | D3: 202402 | E3: 136438571 | F3: 8366793 | G3: =F3/E3 -> 0.061322784 | H3: Agricultura, ganadería y silvicultura | I3: 12 | J3: Cultivos perennes
A4: =LEFT(D4,4) -> 2024 | B4: =RIGHT(D4,2) -> 02 | C4: =DATE(A4,B4,1) -> 45323 | D4: 202402 | E4: 61962058 | F4: 184058 | G4: =F4/E4 -> 0.0029704953 | H4: Agricultura, ganadería y silvicultura | I4: 13 | J4: Producción de semillas y de otras formas de propagación de cultivos agrícolas
A5: =LEFT(D5,4) -> 2024 | B5: =RIGHT(D5,2) -> 02 | C5: =DATE(A5,B5,1) -> 45323 | D5: 202402 | E5: 622363442 | F5: 5116624 | G5: =F5/E5 -> 0.0082212798 | H5: Agricultura, ganadería y silvicultura | I5: 14 | J5: Cría de animales
A6: =LEFT(D6,4) -> 2024 | B6: =RIGHT(D6,2) -> 02 | C6: =DATE(A6,B6,1) -> 45323 | D6: 202402 | E6: 174846840 | F6: 5952704 | G6: =F6/E6 -> 0.034045248 | H6: Agricultura, ganadería y silvicultura | I6: 16 | J6: Servicios de apoyo agrícolas y pecuarios
A7: =LEFT(D7,4) -> 2024 | B7: =RIGHT(D7,2) -> 02 | C7: =DATE(A7,B7,1) -> 45323 | D7: 202402 | E7: 49082 | F7: 0 | G7: =F7/E7 -> 0 | H7: Agricultura, ganadería y silvicultura | I7: 17 | J7: Caza, repoblación de animales de caza y servicios de apoyo
A8: =LEFT(D8,4) -> 2024 | B8: =RIGHT(D8,2) -> 02 | C8: =DATE(A8,B8,1) -> 45323 | D8: 202402 | E8: 386818 | F8: 5485 | G8: =F8/E8 -> 0.014179795 | H8: Agricultura, ganadería y silvicultura | I8: 21 | J8: Silvicultura
A9: =LEFT(D9,4) -> 2024 | B9: =RIGHT(D9,2) -> 02 | C9: =DATE(A9,B9,1) -> 45323 | D9: 202402 | E9: 6172746 | F9: 35502 | G9: =F9/E9 -> 0.0057514111 | H9: Agricultura, ganadería y silvicultura | I9: 22 | J9: Extracción de productos forestales
A10: =LEFT(D10,4) -> 2024 | B10: =RIGHT(D10,2) -> 02 | C10: =DATE(A10,B10,1) -> 45323 | D10: 202402 | E10: 926227 | F10: 10110 | G10: =F10/E10 -> 0.010915251 | H10: Agricultura, ganadería y silvicultura | I10: 24 | J10: Servicios de apoyo a la silvicultura
A11: =LEFT(D11,4) -> 2024 | B11: =RIGHT(D11,2) -> 02 | C11: =DATE(A11,B11,1) -> 45323 | D11: 202402 | E11: 15757632 | F11: 4086 | G11: =F11/E11 -> 0.00025930292 | H11: Pesca | I11: 31 | J11: Pesca y servicios de apoyo
A12: =LEFT(D12,4) -> 2024 | B12: =RIGHT(D12,2) -> 02 | C12: =DATE(A12,B12,1) -> 45323 | D12: 202402 | E12: 1529425 | F12: 302 | G12: =F12/E12 -> 0.00019745983 | H12: Pesca | I12: 32 | J12: Explotación de criaderos de peces, granjas piscícolas y otros frutos acuáticos (acuicultura)
A13: =LEFT(D13,4) -> 2024 | B13: =RIGHT(D13,2) -> 02 | C13: =DATE(A13,B13,1) -> 45323 | D13: 202402 | E13: 75135 | F13: 202 | G13: =F13/E13 -> 0.002688494 | H13: Minería, petróleo y gas | I13: 51 | J13: Extracción y aglomeración de carbón
... A5903: =LEFT(D5903,4) -> 2026 | B5903: =RIGHT(D5903,2) -> 03 | C5903: =DATE(A5903,B5903,1) -> 46082 | D5903: 202603 | E5903: 370373796 | F5903: 70362207 | G5903: =F5903/E5903 -> 0.1899762 | H5903: Otras actividades de servicios comunitarios, sociales y personales | I5903: 999 | J5903: Otros sectores

Sheet Mar26
A1: fecha | B1: actividad | C1: saldo_total (miles de $) | D1: saldo_irregular (miles de $)
A2: 202404 | B2: 11 | C2: 1603723382 | D2: 28879052 | E2: =D2/C2 -> 0.018007502
A3: 202404 | B3: 12 | C3: 167427736 | D3: 8228388 | E3: =D3/C3 -> 0.049145907
A4: 202404 | B4: 13 | C4: 92579005 | D4: 263408 | E4: =D4/C4 -> 0.0028452239
A5: 202404 | B5: 14 | C5: 712800684 | D5: 5908685 | E5: =D5/C5 -> 0.008289393
A6: 202404 | B6: 16 | C6: 208757565 | D6: 6412536 | E6: =D6/C6 -> 0.030717622
A7: 202404 | B7: 17 | C7: 77021 | D7: 0 | E7: =D7/C7 -> 0
A8: 202404 | B8: 21 | C8: 509483 | D8: 6728 | E8: =D8/C8 -> 0.013205544
A9: 202404 | B9: 22 | C9: 6750328 | D9: 34460 | E9: =D9/C9 -> 0.0051049371
A10: 202404 | B10: 24 | C10: 1218690 | D10: 8155 | E10: =D10/C10 -> 0.0066916115
A11: 202404 | B11: 31 | C11: 22542262 | D11: 4809 | E11: =D11/C11 -> 0.00021333263
A12: 202404 | B12: 32 | C12: 3217761 | D12: 302 | E12: =D12/C12 -> 9.3854081e-05
A13: 202404 | B13: 51 | C13: 83038 | D13: 32 | E13: =D13/C13 -> 0.00038536574
... A5449: 202603 | B5449: 999 | C5449: 370373796 | D5449: 70362207 | E5449: =D5449/C5449 -> 0.1899762

Sheet SJ
C6: Saldo de crédito en millones de pesos | E6: Total | F6: Irregular | G6: Tasa
C7: =_xlfn.XLOOKUP(D7,Monitor!$I$5450:$I$5676,Monitor!$J$5450:$J$5676) -> Fabricación de acumuladores, pilas y baterías primarias | D7: 272 | E7: 3072.573 | F7: 3013.162 | G7: =F7/E7 -> 0.98066409
C8: =_xlfn.XLOOKUP(D8,Monitor!$I$5450:$I$5676,Monitor!$J$5450:$J$5676) -> Impresión y servicios relacionados con la impresión | D8: 181 | E8: 1808.792 | F8: 765.669 | G8: =F8/E8 -> 0.42330406
C9: =_xlfn.XLOOKUP(D9,Monitor!$I$5450:$I$5676,Monitor!$J$5450:$J$5676) -> Fabricación de productos elaborados de metal ncp | D9: 259 | E9: 5394.072 | F9: 220.428 | G9: =F9/E9 -> 0.040864861
C10: =_xlfn.XLOOKUP(D10,Monitor!$I$5450:$I$5676,Monitor!$J$5450:$J$5676) -> Reparación y mantenimiento de máquinas y equipo | D10: 331 | E10: 63.715 | F10: 49.57 | G10: =F10/E10 -> 0.77799576
C11: =_xlfn.XLOOKUP(D11,Monitor!$I$5450:$I$5676,Monitor!$J$5450:$J$5676) -> Elaboración de bebidas | D11: 110 | E11: 8279.491 | F11: 32.71 | G11: =F11/E11 -> 0.003950726
C12: =_xlfn.XLOOKUP(D12,Monitor!$I$5450:$I$5676,Monitor!$J$5450:$J$5676) -> Fabricación de productos químicos ncp | D12: 202 | E12: 8500.375 | F12: 17.629 | G12: =F12/E12 -> 0.0020739085
C13: =_xlfn.XLOOKUP(D13,Monitor!$I$5450:$I$5676,Monitor!$J$5450:$J$5676) -> Elaboración de productos alimenticios ncp | D13: 107 | E13: 1548.334 | F13: 16.77 | G13: =F13/E13 -> 0.010830996
C14: =_xlfn.XLOOKUP(D14,Monitor!$I$5450:$I$5676,Monitor!$J$5450:$J$5676) -> Fabricación de maquinaria y equipo de uso especial | D14: 282 | E14: 6717.486 | F14: 15.964 | G14: =F14/E14 -> 0.0023764843 | J14: 3072573.0 | K14: 3013162.0
C15: =_xlfn.XLOOKUP(D15,Monitor!$I$5450:$I$5676,Monitor!$J$5450:$J$5676) -> Fabricación de productos de madera, corcho, paja y materiales trenzables | D15: 162 | E15: 1008.921 | F15: 13.206 | G15: =F15/E15 -> 0.013089231
C16: =_xlfn.XLOOKUP(D16,Monitor!$I$5450:$I$5676,Monitor!$J$5450:$J$5676) -> Fabricación de productos metálicos para uso estructural, tanques, depósitos y generadores de vapor | D16: 251 | E16: 2328.818 | F16: 10.287 | G16: =F16/E16 -> 0.0044172623
C17: =_xlfn.XLOOKUP(D17,Monitor!$I$5450:$I$5676,Monitor!$J$5450:$J$5676) -> Industrias manufactureras ncp | D17: 329 | E17: 147.179 | F17: 8.989 | G17: =F17/E17 -> 0.061075289
C18: =_xlfn.XLOOKUP(D18,Monitor!$I$5450:$I$5676,Monitor!$J$5450:$J$5676) -> Fabricación de productos farmaceúticos, sustancias químicas medicinales y productos botánicos de uso farmaceútico | D18: 210 | E18: 21975.12 | F18: 7.168 | G18: =F18/E18 -> 0.00032618707
C19: =_xlfn.XLOOKUP(D19,Monitor!$I$5450:$I$5676,Monitor!$J$5450:$J$5676) -> Preparación de frutas, hortalizas y legumbres | D19: 103 | E19: 16009.004 | F19: 7.025 | G19: =F19/E19 -> 0.00043881556
C20: =_xlfn.XLOOKUP(D20,Monitor!$I$5450:$I$5676,Monitor!$J$5450:$J$5676) -> Fabricación de equipos y productos informáticos | D20: 262 | E20: 8.442 | F20: 5.623 | G20: =F20/E20 -> 0.66607439
C21: =_xlfn.XLOOKUP(D21,Monitor!$I$5450:$I$5676,Monitor!$J$5450:$J$5676) -> Fabricación de soportes ópticos y magnéticos | D21: 268 | E21: 26.877 | F21: 2.328 | G21: =F21/E21 -> 0.08661681
C22: =_xlfn.XLOOKUP(D22,Monitor!$I$5450:$I$5676,Monitor!$J$5450:$J$5676) -> Fabricación de partes, piezas y accesorios para vehículos automotores y sus motores | D22: 293 | E22: 436.942 | F22: 1.711 | G22: =F22/E22 -> 0.0039158515
C23: =_xlfn.XLOOKUP(D23,Monitor!$I$5450:$I$5676,Monitor!$J$5450:$J$5676) -> Producción y procesamiento de carne y productos cárnicos, excepto pescado | D23: 101 | E23: 288.974 | F23: 1.306 | G23: =F23/E23 -> 0.0045194377
C24: =_xlfn.XLOOKUP(D24,Monitor!$I$5450:$I$5676,Monitor!$J$5450:$J$5676) -> Fabricación de productos minerales no metálicos ncp | D24: 239 | E24: 5001.325 | F24: 0.926 | G24: =F24/E24 -> 0.00018515094
C25: =_xlfn.XLOOKUP(D25,Monitor!$I$5450:$I$5676,Monitor!$J$5450:$J$5676) -> Elaboración de productos de molinería, almidones y productos derivados del almidón | D25: 106 | E25: 40.353 | F25: 0.57 | G25: =F25/E25 -> 0.014125344
C26: =_xlfn.XLOOKUP(D26,Monitor!$I$5450:$I$5676,Monitor!$J$5450:$J$5676) -> Fabricación de productos textiles ncp | D26: 139 | E26: 1098.485 | F26: 0.452 | G26: =F26/E26 -> 0.00041147581
I30: 129044664 | J30: 540002751
I31: 1743122520 | J31: 71522700
I32: 89476298422
I33: =I31/I32 -> 0.019481388
I35: =I30/I31 -> 0.074030748 | J35: =J31/J30 -> 0.13244877
F43: Saldo total: 540002751.0 Mora total: 71522700.0 Tasa: 13.24 %

Sheet MZA
C4: Saldo de crédito en millones de pesos | E4: Total | F4: Irregular | G4: Tasa
C5: =_xlfn.XLOOKUP(D5,Monitor!$I$5450:$I$5676,Monitor!$J$5450:$J$5676) -> Elaboración de bebidas | D5: 110 | E5: 316953.28 | F5: 44463.501 | G5: =F5/E5 -> 0.14028409
C6: =_xlfn.XLOOKUP(D6,Monitor!$I$5450:$I$5676,Monitor!$J$5450:$J$5676) -> Fabricación de motores, generadores y transformadores eléctricos y aparatos de distribución y control de la energía eléctrica | D6: 271 | E6: 22800.423 | F6: 22277.473 | G6: =F6/E6 -> 0.97706402
C7: =_xlfn.XLOOKUP(D7,Monitor!$I$5450:$I$5676,Monitor!$J$5450:$J$5676) -> Fabricación de aparatos de uso doméstico ncp | D7: 275 | E7: 3465.35 | F7: 1095.259 | G7: =F7/E7 -> 0.31606014
C8: =_xlfn.XLOOKUP(D8,Monitor!$I$5450:$I$5676,Monitor!$J$5450:$J$5676) -> Preparación de frutas, hortalizas y legumbres | D8: 103 | E8: 27985.575 | F8: 1035.224 | G8: =F8/E8 -> 0.036991343
C9: =_xlfn.XLOOKUP(D9,Monitor!$I$5450:$I$5676,Monitor!$J$5450:$J$5676) -> Fabricación de productos elaborados de metal ncp | D9: 259 | E9: 8269.848 | F9: 572.588 | G9: =F9/E9 -> 0.069238032
C10: =_xlfn.XLOOKUP(D10,Monitor!$I$5450:$I$5676,Monitor!$J$5450:$J$5676) -> Fabricación de productos de madera, corcho, paja y materiales trenzables | D10: 162 | E10: 4092.312 | F10: 433.453 | G10: =F10/E10 -> 0.10591885
C11: =_xlfn.XLOOKUP(D11,Monitor!$I$5450:$I$5676,Monitor!$J$5450:$J$5676) -> Fabricación de productos farmaceúticos, sustancias químicas medicinales y productos botánicos de uso farmaceútico | D11: 210 | E11: 1704.466 | F11: 311.606 | G11: =F11/E11 -> 0.18281738
C12: =_xlfn.XLOOKUP(D12,Monitor!$I$5450:$I$5676,Monitor!$J$5450:$J$5676) -> Industrias manufactureras ncp | D12: 329 | E12: 1174.478 | F12: 267.193 | G12: =F12/E12 -> 0.22749937
C13: =_xlfn.XLOOKUP(D13,Monitor!$I$5450:$I$5676,Monitor!$J$5450:$J$5676) -> Producción y procesamiento de carne y productos cárnicos, excepto pescado | D13: 101 | E13: 9439.266 | F13: 220.094 | G13: =F13/E13 -> 0.023316855
C14: =_xlfn.XLOOKUP(D14,Monitor!$I$5450:$I$5676,Monitor!$J$5450:$J$5676) -> Fabricación de maquinaria y equipo de uso especial | D14: 282 | E14: 17349.277 | F14: 167.305 | G14: =F14/E14 -> 0.0096433413
C15: =_xlfn.XLOOKUP(D15,Monitor!$I$5450:$I$5676,Monitor!$J$5450:$J$5676) -> Elaboración de productos alimenticios ncp | D15: 107 | E15: 4616.641 | F15: 151.873 | G15: =F15/E15 -> 0.032896862
C16: =_xlfn.XLOOKUP(D16,Monitor!$I$5450:$I$5676,Monitor!$J$5450:$J$5676) -> Fabricación de muebles y colchones | D16: 310 | E16: 1709.109 | F16: 89.831 | G16: =F16/E16 -> 0.052560135
... C24: =_xlfn.XLOOKUP(D24,Monitor!$I$5450:$I$5676,Monitor!$J$5450:$J$5676) -> Instalación de maquinaria y equipos industriales | D24: 332 | E24: 508.474 | F24: 22.887 | G24: =F24/E24 -> 0.045011151

Sheet Indice
B1: Hoja | C1: Link
B2: Calidad de cartera | C2: https://www.bcra.gob.ar/archivos/Pdfs/PublicacionesEstadisticas/informes/InfBanc_Anexo.xlsx
B3: Calidad de cartera (Lineas) | C3: https://www.bcra.gob.ar/archivos/Pdfs/PublicacionesEstadisticas/informes/InfBanc_Anexo.xlsx
B4: Cheques rechazados | C4: https://www.bcra.gob.ar/informe-de-pagos-minoristas/
B5: Monitor | C5: Con estos datos, extraídos del la CENDEU (Central de Deudores de BCRA), se construyen las tablas dinamicas para poder armar los graficos y series históricas
B6: Solo Sectores
B7: Graficos

Sheet Calidad de Cartera
A1: Calidad de Cartera Crediticia
A3: Sistema financiero
A4: En porcentaje | B4: 37591 | C4: 37956 | D4: 38322 | E4: 38687 | F4: 39052 | G4: 39417 | H4: 39783 | I4: 40148 | J4: 40179 | K4: 40210 | L4: 40238 | M4: 40269 | N4: 40299 | O4: 40330 | P4: 40360 | Q4: 40391 | R4: 40422 | S4: 40452 | T4: 40483 | U4: 40513 | V4: 40544 | W4: 40575 | X4: 40603 | Y4: 40634 | Z4: 40664 | AA4: 40695 | AB4: 40725 | AC4: 40756 | AD4: 40787 | AE4: 40817 | AF4: 40848 | AG4: 40878 | AH4: 40909 | AI4: 40940 | AJ4: 40969 | AK4: 41000 | AL4: 41030 | AM4: 41061 | AN4: 41091 | AO4: 41122 | AP4: 41153 | AQ4: 41183 | AR4: 41214 | AS4: 41244 | AT4: 41275 | AU4: 41306 | AV4: 41334 | AW4: 41365 | AX4: 41395 | AY4: 41426 | AZ4: 41456 | BA4: 41487 | BB4: 41518 | BC4: 41548 | BD4: 41579 | BE4: 41609 | BF4: 41640 | BG4: 41671 | BH4: 41699 | BI4: 41730 | BJ4: 41760 | BK4: 41791 | BL4: 41821 | BM4: 41852 | BN4: 41883 | BO4: 41913 | BP4: 41944 | BQ4: 41974 | BR4: 42005 | BS4: 42036 | BT4: 42064 | BU4: 42095 | BV4: 42125 | BW4: 42156 | BX4: 42186 | BY4: 42217 | BZ4: 42248 | CA4: 42278 | CB4: 42309 | CC4: 42339 | CD4: 42370 | CE4: 42401 | CF4: 42430 | CG4: 42461 | CH4: 42491 | CI4: 42522 | CJ4: 42552 | CK4: 42583 | CL4: 42614 | CM4: 42644 | CN4: 42675 | CO4: 42705 | CP4: 42736 | CQ4: 42767 | CR4: 42795 | CS4: 42826 | CT4: 42856 | CU4: 42887 | CV4: 42917 | CW4: 42948 | CX4: 42979 | CY4: 43009 | CZ4: 43040 | DA4: 43070 | DB4: 43101 | DC4: 43132 | DD4: 43160 | DE4: 43191 | DF4: 43221 | DG4: 43252 | DH4: 43282 | DI4: 43313 | DJ4: 43344 | DK4: 43374 | DL4: 43405 | DM4: 43435 | DN4: 43466 | DO4: 43497 | DP4: 43525 | DQ4: 43556 | DR4: 43586 | DS4: 43617 | DT4: 43647 | DU4: 43678 | DV4: 43709 | DW4: 43739 | DX4: 43770 | DY4: 43800 | DZ4: 43831 | EA4: 43862 | EB4: 43891 | EC4: 43922 | ED4: 43952 | EE4: 43983 | EF4: 44013 | EG4: 44044 | EH4: 44075 | EI4: 44105 | EJ4: 44136 | EK4: 44166 | EL4: 44197 | EM4: 44228 | EN4: 44256 | EO4: 44287 | EP4: 44317 | EQ4: 44348 | ER4: 44378 | ES4: 44409 | ET4: 44440 | EU4: 44470 | EV4: 44501 | EW4: 44531 | EX4: 44562 | EY4: 44593 | EZ4: 44621 | FA4: 44652 | FB4: 44682 | FC4: 44713 | FD4: 44743 | FE4: 44774 | FF4: 44805 | FG4: 44835 | FH4: 44866 | FI4: 44896 | FJ4: 44927 | FK4: 44958 | FL4: 44986 | FM4: 45017 | FN4: 45047 | FO4: 45078 | FP4: 45108 | FQ4: 45139 | FR4: 45170 | FS4: 45200 | FT4: 45231 | FU4: 45261 | FV4: 45292 | FW4: 45323 | FX4: 45352 | FY4: 45383 | FZ4: 45413 | GA4: 45444 | GB4: 45474 | GC4: 45505 | GD4: 45536 | GE4: 45566 | GF4: 45597 | GG4: 45627 | GH4: 45658 | GI4: 45689 | GJ4: 45717 | GK4: 45748 | GL4: 45778 | GM4: 45809 | GN4: 45839 | GO4: 45870 | GP4: 45901 | GQ4: 45931 | GR4: 45962 | GS4: 45992 | GT4: 46023 | GU4: 46054
A5: Cartera irregular total | B5: 18.088446 | C5: 17.70293 | D5: 10.685333 | E5: 5.1808434 | F5: 3.3907142 | G5: 2.7268475 | H5: 2.679206 | I5: 2.9819582 | J5: 3.0053087 | K5: 2.9031719 | L5: 2.8029277 | M5: 2.6862036 | N5: 2.645191 | O5: 2.4758288 | P5: 2.4329131 | Q5: 2.3587915 | R5: 2.1790951 | S5: 2.0868576 | T5: 1.9827663 | U5: 1.8439958 | V5: 1.7719505 | W5: 1.7049496 | X5: 1.6292849 | Y5: 1.5768273 | Z5: 1.5409429 | AA5: 1.4621717 | AB5: 1.4115999 | AC5: 1.3710009 | AD5: 1.2593854 | AE5: 1.2560386 | AF5: 1.2206176 | AG5: 1.227708 | AH5: 1.3011171 | AI5: 1.3340316 | AJ5: 1.3633645 | AK5: 1.4401407 | AL5: 1.5157052 | AM5: 1.4666915 | AN5: 1.5083234 | AO5: 1.5300937 | AP5: 1.5177816 | AQ5: 1.5697867 | AR5: 1.5502236 | AS5: 1.5367359 | AT5: 1.5834257 | AU5: 1.646368 | AV5: 1.6184521 | AW5: 1.6771206 | AX5: 1.7032666 | AY5: 1.699406 | AZ5: 1.6845671 | BA5: 1.6694359 | BB5: 1.6232721 | BC5: 1.6025339 | BD5: 1.560999 | BE5: 1.5337287 | BF5: 1.5649294 | BG5: 1.5992335 | BH5: 1.6476336 | BI5: 1.7055161 | BJ5: 1.8116337 | BK5: 1.7928942 | BL5: 1.8128119 | BM5: 1.8626924 | BN5: 1.8114161 | BO5: 1.8250771 | BP5: 1.8274452 | BQ5: 1.7925587 | BR5: 1.8127613 | BS5: 1.8102539 | BT5: 1.7807497 | BU5: 1.8442048 | BV5: 1.8250296 | BW5: 1.7541396 | BX5: 1.7154597 | BY5: 1.6746478 | BZ5: 1.6149292 | CA5: 1.5478835 | CB5: 1.5921206 | CC5: 1.5742013 | CD5: 1.6367133 | CE5: 1.6534374 | CF5: 1.6455892 | CG5: 1.6679204 | CH5: 1.6927177 | CI5: 1.7203216 | CJ5: 1.748702 | CK5: 1.8006627 | CL5: 1.7512855 | CM5: 1.7607589 | CN5: 1.7037473 | CO5: 1.7002775 | CP5: 1.7719349 | CQ5: 1.7871076 | CR5: 1.8192552 | CS5: 1.8473039 | CT5: 1.8869664 | CU5: 1.894586 | CV5: 1.8368429 | CW5: 1.7923907 | CX5: 1.7376704 | CY5: 1.7415992 | CZ5: 1.778564 | DA5: 1.7347993 | DB5: 1.8051381 | DC5: 1.8284657 | DD5: 1.8765495 | DE5: 1.9132269 | DF5: 2.0440632 | DG5: 2.0274354 | DH5: 2.1533016 | DI5: 2.1242783 | DJ5: 2.1995886 | DK5: 2.4765806 | DL5: 2.7161855 | DM5: 2.9577855 | DN5: 3.3666436 | DO5: 3.9520404 | DP5: 4.1434187 | DQ5: 4.2695428 | DR5: 4.575215 | DS5: 4.6459697 | DT5: 4.7550432 | DU5: 4.7594988 | DV5: 4.8516383 | DW5: 4.8752019 | DX5: 5.0594861 | DY5: 5.7029147 | DZ5: 5.9736012 | EA5: 6.0958475 | EB5: 5.2659882 | EC5: 5.2325564 | ED5: 5.19981 | EE5: 5.0132049 | EF5: 5.0508861 | EG5: 4.8808033 | EH5: 4.7961359 | EI5: 4.5283915 | EJ5: 4.3996765 | EK5: 4.150064 | EL5: 4.1136937 | EM5: 4.0218794 | EN5: 4.1233251 | EO5: 4.3878877 | EP5: 4.4850959 | EQ5: 5.0439308 | ER5: 5.5656807 | ES5: 5.2928818 | ET5: 5.0152028 | EU5: 4.8740832 | EV5: 4.551054 | EW5: 4.2921129 | EX5: 4.3263639 | EY5: 4.1489638 | EZ5: 3.866044 | FA5: 3.5420084 | FB5: 3.35231 | FC5: 3.2056702 | FD5: 3.1172651 | FE5: 3.1227188 | FF5: 3.0845204 | FG5: 3.0675259 | FH5: 3.0142734 | FI5: 3.0940134 | FJ5: 3.1740153 | FK5: 3.1528107 | FL5: 3.1458493 | FM5: 3.0266417 | FN5: 2.9970731 | FO5: 2.9754087 | FP5: 3.0022394 | FQ5: 3.0793214 | FR5: 2.9494669 | FS5: 2.7191557 | FT5: 2.6006328 | FU5: 3.5490485 | FV5: 3.4126484 | FW5: 2.0218946 | FX5: 1.9585484 | FY5: 1.92439 | FZ5: 1.9048722 | GA5: 1.8222641 | GB5: 1.7291376 | GC5: 1.6478676 | GD5: 1.6080224 | GE5: 1.5252289 | GF5: 1.5336122 | GG5: 1.564008 | GH5: 1.6481877 | GI5: 1.7816297 | GJ5: 1.9626867 | GK5: 2.1782306 | GL5: 2.5494297 | GM5: 2.850967 | GN5: 3.1286348 | GO5: 3.6318047 | GP5: 3.9921831 | GQ5: 4.3798525 | GR5: 5.008001 | GS5: 5.294553 | GT5: 6.0591085 | GU5: 6.395112
A6: Previsiones / Cartera irregular | B6: 72.270763 | C6: 76.788327 | D6: 97.759951 | E6: 115.31339 | F6: 108.17852 | G6: 115.19579 | H6: 117.04632 | I6: 115.3269 | J6: 115.15886 | K6: 117.61995 | L6: 119.0673 | M6: 121.19235 | N6: 121.47004 | O6: 124.98434 | P6: 126.17244 | Q6: 130.81154 | R6: 135.29829 | S6: 138.32157 | T6: 141.56583 | U6: 147.74462 | V6: 150.53951 | W6: 154.82997 | X6: 158.24564 | Y6: 161.15801 | Z6: 161.65161 | AA6: 160.34521 | AB6: 164.97356 | AC6: 168.946 | AD6: 175.19774 | AE6: 177.28423 | AF6: 176.89603 | AG6: 176.08623 | AH6: 168.91532 | AI6: 164.69015 | AJ6: 162.69404 | AK6: 155.39399 | AL6: 149.2576 | AM6: 152.48573 | AN6: 148.94317 | AO6: 148.09233 | AP6: 147.81145 | AQ6: 143.18261 | AR6: 144.10979 | AS6: 144.3804 | AT6: 141.57902 | AU6: 138.11138 | AV6: 139.79168 | AW6: 134.08932 | AX6: 134.20281 | AY6: 133.87237 | AZ6: 135.86318 | BA6: 136.86515 | BB6: 138.41332 | BC6: 140.23252 | BD6: 141.54104 | BE6: 150.45524 | BF6: 153.31181 | BG6: 152.27221 | BH6: 149.04766 | BI6: 145.51384 | BJ6: 140.50042 | BK6: 140.49648 | BL6: 140.16748 | BM6: 139.11368 | BN6: 141.46045 | BO6: 141.88689 | BP6: 141.75302 | BQ6: 141.57322 | BR6: 140.60265 | BS6: 140.82805 | BT6: 140.94875 | BU6: 138.01336 | BV6: 138.59055 | BW6: 140.79923 | BX6: 143.0766 | BY6: 143.77508 | BZ6: 147.93382 | CA6: 151.27386 | CB6: 146.47401 | CC6: 150.18076 | CD6: 145.91075 | CE6: 145.83199 | CF6: 145.81699 | CG6: 146.81735 | CH6: 144.86578 | CI6: 140.90479 | CJ6: 139.71086 | CK6: 138.97308 | CL6: 141.62963 | CM6: 140.1933 | CN6: 143.01482 | CO6: 139.82263 | CP6: 136.87095 | CQ6: 136.56027 | CR6: 134.88133 | CS6: 135.52175 | CT6: 133.14691 | CU6: 132.78889 | CV6: 135.29897 | CW6: 137.83411 | CX6: 143.0162 | CY6: 143.09769 | CZ6: 140.74224 | DA6: 150.60742 | DB6: 136.58321 | DC6: 136.49471 | DD6: 135.04673 | DE6: 132.55741 | DF6: 126.33482 | DG6: 127.00138 | DH6: 124.68627 | DI6: 125.25722 | DJ6: 125.65736 | DK6: 120.61404 | DL6: 126.72323 | DM6: 121.1963 | DN6: 112.55315 | DO6: 91.120475 | DP6: 92.698061 | DQ6: 93.198537 | DR6: 90.903015 | DS6: 92.947907 | DT6: 92.272053 | DU6: 91.35275 | DV6: 94.419715 | DW6: 95.004131 | DX6: 94.221402 | DY6: 94.126243 | DZ6: 83.653489 | EA6: 83.390561 | EB6: 96.104312 | EC6: 100.67183 | ED6: 106.85381 | EE6: 110.60866 | EF6: 110.9899 | EG6: 112.15689 | EH6: 114.97992 | EI6: 119.80676 | EJ6: 126.31111 | EK6: 136.32399 | EL6: 136.52038 | EM6: 139.61664 | EN6: 133.67819 | EO6: 126.19275 | EP6: 123.59209 | EQ6: 109.87846 | ER6: 101.37187 | ES6: 104.82337 | ET6: 106.89086 | EU6: 107.57543 | EV6: 108.26263 | EW6: 110.04569 | EX6: 108.34777 | EY6: 110.51869 | EZ6: 112.8924 | FA6: 115.25591 | FB6: 117.04515 | FC6: 116.46505 | FD6: 116.97783 | FE6: 115.80003 | FF6: 125.12489 | FG6: 123.25338 | FH6: 126.81522 | FI6: 128.4185 | FJ6: 124.89327 | FK6: 124.74532 | FL6: 123.67452 | FM6: 125.05776 | FN6: 125.94603 | FO6: 124.51039 | FP6: 122.55162 | FQ6: 122.05141 | FR6: 120.69621 | FS6: 126.36418 | FT6: 128.71412 | FU6: 140.37707 | FV6: 136.47839 | FW6: 167.50127 | FX6: 175.1256 | FY6: 155.19121 | FZ6: 149.68542 | GA6: 152.11122 | GB6: 153.39066 | GC6: 160.84806 | GD6: 163.20099 | GE6: 171.91549 | GF6: 165.3661 | GG6: 158.99064 | GH6: 156.46598 | GI6: 148.7123 | GJ6: 143.06962 | GK6: 137.37817 | GL6: 126.64772 | GM6: 117.10571 | GN6: 113.05354 | GO6: 107.05969 | GP6: 102.57048 | GQ6: 101.30331 | GR6: 97.676426 | GS6: 93.672113 | GT6: 89.342267 | GU6: 90.140566
A7: (Cartera irregular - Previsiones) / Financiaciones | B7: 5.0157883 | C7: 4.1091462 | D7: 0.23935665 | E7: -0.79336297 | F7: -0.27731026 | G7: -0.41436597 | H7: -0.45670591 | I7: -0.45704184 | J7: -0.45557064 | K7: -0.51153734 | L7: -0.53444272 | M7: -0.56926972 | N7: -0.5679237 | O7: -0.61856938 | P7: -0.63675266 | Q7: -0.72677996 | R7: -0.76918341 | S7: -0.79971669 | T7: -0.82415323 | U7: -0.88040875 | V7: -0.89553514 | W7: -0.93482336 | X7: -0.94898737 | Y7: -0.96435613 | Z7: -0.95001609 | AA7: -0.88235056 | AB7: -0.91716667 | AC7: -0.94525027 | AD7: -0.94702939 | AE7: -0.97071968 | AF7: -0.93860651 | AG7: -0.93411676 | AH7: -0.89666902 | AI7: -0.86298708 | AJ7: -0.8547482 | AK7: -0.79775138 | AL7: -0.74660003 | AM7: -0.76980378 | AN7: -0.73822131 | AO7: -0.73585772 | AP7: -0.72567345 | AQ7: -0.67787484 | AR7: -0.68380038 | AS7: -0.68200959 | AT7: -0.65837284 | AU7: -0.62745358 | AV7: -0.64400929 | AW7: -0.571719 | AX7: -0.58256499 | AY7: -0.57562912 | AZ7: -0.60413934 | BA7: -0.61544009 | BB7: -0.62355264 | BC7: -0.64473974 | BD7: -0.64845529 | BE7: -0.77384649 | BF7: -0.83429222 | BG7: -0.83595474 | BH7: -0.80812582 | BI7: -0.77624587 | BJ7: -0.73371927 | BK7: -0.72605905 | BL7: -0.7281608 | BM7: -0.72856755 | BN7: -0.75102133 | BO7: -0.76446804 | BP7: -0.76301353 | BQ7: -0.74522442 | BR7: -0.73602915 | BS7: -0.73909127 | BT7: -0.72919469 | BU7: -0.70104418 | BV7: -0.70428892 | BW7: -0.71567549 | BX7: -0.73896167 | BY7: -0.73307845 | BZ7: -0.77409725 | CA7: -0.79365954 | CB7: -0.73992232 | CC7: -0.78994621 | CD7: -0.75142737 | CE7: -0.75780321 | CF7: -0.75395939 | CG7: -0.78087605 | CH7: -0.75945105 | CI7: -0.70369401 | CJ7: -0.6944246 | CK7: -0.70177372 | CL7: -0.72905376 | CM7: -0.70770711 | CN7: -0.73286389 | CO7: -0.6770953 | CP7: -0.65332922 | CQ7: -0.65337138 | CR7: -0.6345804 | CS7: -0.65619469 | CT7: -0.62547107 | CU7: -0.62121376 | CV7: -0.64838655 | CW7: -0.67813501 | CX7: -0.74747984 | CY7: -0.75058903 | CZ7: -0.72462684 | DA7: -0.87793711 | DB7: -0.66037752 | DC7: -0.66729321 | DD7: -0.65766918 | DE7: -0.62289714 | DF7: -0.53830027 | DG7: -0.54743549 | DH7: -0.53156979 | DI7: -0.5365336 | DJ7: -0.56435636 | DK7: -0.5105232 | DL7: -0.72585246 | DM7: -0.62694106 | DN7: -0.42261979 | DO7: 0.35092242 | DP7: 0.30254993 | DQ7: 0.29039137 | DR7: 0.41620663 | DS7: 0.32763812 | DT7: 0.36746721 | DU7: 0.41156577 | DV7: 0.27073525 | DW7: 0.24355871 | DX7: 0.29236736 | DY7: 0.33497537 | DZ7: 0.97647538 | EA7: 1.0124861 | EB7: 0.20514646 | EC7: -0.035154048 | ED7: -0.35638492 | EE7: -0.53183398 | EF7: -0.55508733 | EG7: -0.59335412 | EH7: -0.71845737 | EI7: -0.89692743 | EJ7: -1.1576036 | EK7: -1.5074689 | EL7: -1.5023365 | EM7: -1.5933333 | EN7: -1.3886613 | EO7: -1.1493084 | EP7: -1.0581279 | EQ7: -0.49826262 | ER7: -0.076354015 | ES7: -0.2552953 | ET7: -0.34559061 | EU7: -0.36923289 | EV7: -0.37603669 | EW7: -0.43117238 | EX7: -0.36115502 | EY7: -0.43641658 | EZ7: -0.49842588 | FA7: -0.54036576 | FB7: -0.57140634 | FC7: -0.52781523 | FD7: -0.52924389 | FE7: -0.49339057 | FF7: -0.77498235 | FG7: -0.71330353 | FH7: -0.80828396 | FI7: -0.8792723 | FJ7: -0.79011606 | FK7: -0.78017301 | FL7: -0.74476468 | FM7: -0.75840846 | FN7: -0.77762139 | FO7: -0.72928427 | FP7: -0.67705362 | FQ7: -0.67903381 | FR7: -0.61042786 | FS7: -0.71688305 | FT7: -0.74674875 | FU7: -1.4330018 | FV7: -1.2448792 | FW7: -1.3648046 | FX7: -1.4713712 | FY7: -1.062094 | FZ7: -0.9464437 | GA7: -0.94960405 | GB7: -0.92319793 | GC7: -1.0026955 | GD7: -1.016286 | GE7: -1.0968758 | GF7: -1.0024625 | GG7: -0.9226183 | GH7: -0.93066528 | GI7: -0.86787282 | GJ7: -0.84532175 | GK7: -0.81418276 | GL7: -0.67936486 | GM7: -0.48767819 | GN7: -0.40839759 | GO7: -0.2563941 | GP7: -0.10261845 | GQ7: -0.057082967 | GR7: 0.1163646 | GS7: 0.33503335 | GT7: 0.6457636 | GU7: 0.63052182
A8: (Cartera irregular - Previsiones) / PN | B8: 18.155828 | C8: 13.263905 | D8: 0.77563013 | E8: -2.5793981 | F8: -0.90810523 | G8: -1.5534313 | H8: -1.7855542 | I8: -1.6622871 | J8: -1.6454062 | K8: -1.8395793 | L8: -1.9250425 | M8: -2.1484935 | N8: -2.2256698 | O8: -2.439986 | P8: -2.4857613 | Q8: -2.8518986 | R8: -3.0582667 | S8: -3.1938917 | T8: -3.3204855 | U8: -3.6295845 | V8: -3.6934363 | W8: -3.9008653 | X8: -4.0933571 | Y8: -4.276603 | Z8: -4.2731031 | AA8: -4.0949609 | AB8: -4.3225458 | AC8: -4.5001578 | AD8: -4.6379077 | AE8: -4.7419079 | AF8: -4.6215014 | AG8: -4.5612043 | AH8: -4.3191684 | AI8: -4.1495789 | AJ8: -4.0724164 | AK8: -3.7847582 | AL8: -3.5337451 | AM8: -3.652851 | AN8: -3.4879892 | AO8: -3.483699 | AP8: -3.4171909 | AQ8: -3.2179259 | AR8: -3.2681239 | AS8: -3.3531731 | AT8: -3.1901126 | AU8: -2.9892563 | AV8: -3.0594075 | AW8: -2.7165752 | AX8: -2.773238 | AY8: -2.7802084 | AZ8: -2.8947248 | BA8: -2.9554289 | BB8: -2.9944254 | BC8: -3.0718347 | BD8: -3.1031241 | BE8: -3.719245 | BF8: -3.7737975 | BG8: -3.7012666 | BH8: -3.5197463 | BI8: -3.3528057 | BJ8: -3.1073755 | BK8: -3.0824866 | BL8: -3.0303351 | BM8: -2.9891261 | BN8: -3.072861 | BO8: -3.1106203 | BP8: -3.0978171 | BQ8: -3.0625498 | BR8: -2.9565389 | BS8: -2.933456 | BT8: -2.9190091 | BU8: -2.829735 | BV8: -2.8575596 | BW8: -2.9461362 | BX8: -3.0050227 | BY8: -2.9855808 | BZ8: -3.1279047 | CA8: -3.2233055 | CB8: -3.0344959 | CC8: -3.2734718 | CD8: -3.0518708 | CE8: -3.0068602 | CF8: -2.9520965 | CG8: -3.1033314 | CH8: -2.9870015 | CI8: -2.7454759 | CJ8: -2.6804816 | CK8: -2.7072544 | CL8: -2.8301893 | CM8: -2.7622954 | CN8: -2.9104243 | CO8: -2.73678 | CP8: -2.6296495 | CQ8: -2.604343 | CR8: -2.5168174 | CS8: -2.6384976 | CT8: -2.5381914 | CU8: -2.5219293 | CV8: -2.637491 | CW8: -2.7971931 | CX8: -3.1455836 | CY8: -3.2096777 | CZ8: -3.1434759 | DA8: -3.901756 | DB8: -2.6411703 | DC8: -2.6638942 | DD8: -2.7100779 | DE8: -2.6211338 | DF8: -2.357568 | DG8: -2.4170975 | DH8: -2.3202212 | DI8: -2.4472688 | DJ8: -2.5079617 | DK8: -2.1506147 | DL8: -3.097009 | DM8: -2.5135165 | DN8: -1.6316128 | DO8: 1.3261962 | DP8: 1.1608334 | DQ8: 1.1371315 | DR8: 1.6058431 | DS8: 1.2148387 | DT8: 1.3303854 | DU8: 1.6251907 | DV8: 0.98286332 | DW8: 0.87913015 | DX8: 1.0164831 | DY8: 1.1160921 | DZ8: 2.5487306 | EA8: 2.610645 | EB8: 0.53016198 | EC8: -0.09088994 | ED8: -0.90329582 | EE8: -1.3394827 | EF8: -1.3720278 | EG8: -1.4227712 | EH8: -1.7016898 | EI8: -2.1189693 | EJ8: -2.7193459 | EK8: -3.4979153 | EL8: -3.3794801 | EM8: -3.5128082 | EN8: -2.9873801 | EO8: -2.445161 | EP8: -2.2183326 | EQ8: -1.0396283 | ER8: -0.15685482 | ES8: -0.51844549 | ET8: -0.70041549 | EU8: -0.75296572 | EV8: -0.78120958 | EW8: -0.89768477 | EX8: -0.72465323 | EY8: -0.8638254 | EZ8: -0.96263939 | FA8: -1.0263318 | FB8: -1.0825994 | FC8: -1.0128146 | FD8: -0.97765007 | FE8: -0.87695804 | FF8: -1.3155988 | FG8: -1.1901395 | FH8: -1.3357691 | FI8: -1.4137409 | FJ8: -1.2273244 | FK8: -1.186243 | FL8: -1.1410038 | FM8: -1.2091581 | FN8: -1.2190275 | FO8: -1.1313418 | FP8: -1.0256725 | FQ8: -1.0031907 | FR8: -0.86186786 | FS8: -1.0027617 | FT8: -0.94813896 | FU8: -1.5549217 | FV8: -1.2395338 | FW8: -1.2773354 | FX8: -1.3378303 | FY8: -0.94476588 | FZ8: -0.94424879 | GA8: -1.023251 | GB8: -1.059917 | GC8: -1.2134973 | GD8: -1.3109138 | GE8: -1.5210765 | GF8: -1.4504104 | GG8: -1.4378671 | GH8: -1.4731239 | GI8: -1.430536 | GJ8: -1.4589261 | GK8: -1.4471746 | GL8: -1.2587833 | GM8: -0.9679346 | GN8: -0.84336999 | GO8: -0.54891117 | GP8: -0.22659579 | GQ8: -0.12102287 | GR8: 0.24882098 | GS8: 0.72518682 | GT8: 1.3709465 | GU8: 1.3124861
A9: Al sector privado no financiero | B9: 38.63356 | C9: 33.483545 | D9: 18.556685 | E9: 7.6066468 | F9: 4.4565435 | G9: 3.2418579 | H9: 3.1083847 | I9: 3.4668283 | J9: 3.509483 | K9: 3.4146482 | L9: 3.2835899 | M9: 3.1331575 | N9: 3.0736082 | O9: 2.8863323 | P9: 2.8307834 | Q9: 2.7431277 | R9: 2.5277204 | S9: 2.4126157 | T9: 2.2823394 | U9: 2.1170229 | V9: 2.0371113 | W9: 1.9558797 | X9: 1.8639643 | Y9: 1.8002323 | Z9: 1.7508362 | AA9: 1.6780152 | AB9: 1.6130688 | AC9: 1.5577688 | AD9: 1.4287378 | AE9: 1.4209001 | AF9: 1.3898258 | AG9: 1.3955984 | AH9: 1.4728128 | AI9: 1.5166172 | AJ9: 1.5496389 | AK9: 1.6364738 | AL9: 1.721243 | AM9: 1.6623538 | AN9: 1.7162556 | AO9: 1.7341852 | AP9: 1.7189325 | AQ9: 1.7747571 | AR9: 1.7470838 | AS9: 1.7345487 | AT9: 1.7853027 | AU9: 1.8516412 | AV9: 1.8192052 | AW9: 1.8842359 | AX9: 1.9182132 | AY9: 1.9107199 | AZ9: 1.8979216 | BA9: 1.8783169 | BB9: 1.8235728 | BC9: 1.7975155 | BD9: 1.7582741 | BE9: 1.7325824 | BF9: 1.7601537 | BG9: 1.8020389 | BH9: 1.8536536 | BI9: 1.9181711 | BJ9: 2.0374395 | BK9: 2.0157531 | BL9: 2.0338288 | BM9: 2.0878134 | BN9: 2.026998 | BO9: 2.0343603 | BP9: 2.0286348 | BQ9: 1.9900644 | BR9: 2.0142078 | BS9: 1.9997715 | BT9: 1.9920657 | BU9: 2.0578168 | BV9: 2.0333923 | BW9: 1.9466594 | BX9: 1.8882499 | BY9: 1.8347257 | BZ9: 1.7653617 | CA9: 1.6863372 | CB9: 1.7289317 | CC9: 1.7368418 | CD9: 1.782455 | CE9: 1.812754 | CF9: 1.8338873 | CG9: 1.8595552 | CH9: 1.8822242 | CI9: 1.9107531 | CJ9: 1.9391266 | CK9: 1.9130597 | CL9: 1.8623928 | CM9: 1.8666758 | CN9: 1.8067305 | CO9: 1.8366055 | CP9: 1.9120598 | CQ9: 1.9180292 | CR9: 1.9487884 | CS9: 1.9755795 | CT9: 2.0140822 | CU9: 2.0240679 | CV9: 1.9595064 | CW9: 1.9087358 | CX9: 1.848241 | CY9: 1.8475357 | CZ9: 1.8849939 | DA9: 1.8303637 | DB9: 1.8963376 | DC9: 1.9189478 | DD9: 1.9677041 | DE9: 2.0100927 | DF9: 2.1568379 | DG9: 2.13709 | DH9: 2.2701761 | DI9: 2.2349427 | DJ9: 2.3109625 | DK9: 2.6022475 | DL9: 2.8518179 | DM9: 3.1085722 | DN9: 3.5350704 | DO9: 3.841028 | DP9: 4.0341718 | DQ9: 4.1713657 | DR9: 4.4775706 | DS9: 4.5354028 | DT9: 4.6705323 | DU9: 4.7032178 | DV9: 4.7966873 | DW9: 4.8754897 | DX9: 5.0433739 | DY9: 5.7484931 | DZ9: 6.0259373 | EA9: 6.15756 | EB9: 5.2899583 | EC9: 5.2020482 | ED9: 5.16438 | EE9: 4.9761603 | EF9: 5.0113657 | EG9: 4.7936434 | EH9: 4.5206801 | EI9: 4.2436141 | EJ9: 4.1253113 | EK9: 3.8612578 | EL9: 3.8472391 | EM9: 3.7620254 | EN9: 3.8704053 | EO9: 4.1632586 | EP9: 4.265936 | EQ9: 4.8626399 | ER9: 5.4190134 | ES9: 5.3236128 | ET9: 5.0384599 | EU9: 4.8950536 | EV9: 4.5863671 | EW9: 4.325365 | EX9: 4.3361336 | EY9: 4.1951623 | EZ9: 3.8971939 | FA9: 3.5641141 | FB9: 3.3692355 | FC9: 3.2268929 | FD9: 3.1265686 | FE9: 3.1383325 | FF9: 3.1054381 | FG9: 3.0885359 | FH9: 3.034209 | FI9: 3.1348352 | FJ9: 3.2085158 | FK9: 3.1899723 | FL9: 3.1889828 | FM9: 3.0692125 | FN9: 3.0400146 | FO9: 3.0450177 | FP9: 3.0608923 | FQ9: 3.1518446 | FR9: 3.0214517 | FS9: 2.8153592 | FT9: 2.6547149 | FU9: 3.6544321 | FV9: 3.5133412 | FW9: 1.914109 | FX9: 1.8637448 | FY9: 1.8393846 | FZ9: 1.8406615 | GA9: 1.7714306 | GB9: 1.6781996 | GC9: 1.6048736 | GD9: 1.57237 | GE9: 1.4942636 | GF9: 1.5053276 | GG9: 1.5429641 | GH9: 1.6303242 | GI9: 1.7733252 | GJ9: 1.9658225 | GK9: 2.1881766 | GL9: 2.5806095 | GM9: 2.9094545 | GN9: 3.1871426 | GO9: 3.7218179 | GP9: 4.1560916 | GQ9: 4.5476633 | GR9: 5.2256542 | GS9: 5.546394 | GT9: 6.3506802 | GU9: 6.7064499
A10: Previsiones / Cartera irregular | B10: 73.835066 | C10: 79.037687 | D10: 96.900905 | E10: 114.84857 | F10: 107.60644 | G10: 114.43452 | H10: 116.37087 | I10: 111.76157 | J10: 111.94667 | K10: 114.41764 | L10: 115.871 | M10: 117.98686 | N10: 117.55463 | O10: 120.88558 | P10: 122.0713 | Q10: 126.4298 | R10: 130.74371 | S10: 133.69657 | T10: 136.84794 | U10: 142.77998 | V10: 145.46414 | W10: 149.66915 | X10: 152.90501 | Y10: 155.79452 | Z10: 156.29417 | AA10: 154.95863 | AB10: 159.37768 | AC10: 163.36076 | AD10: 169.29334 | AE10: 171.49446 | AF10: 171.82015 | AG10: 171.15996 | AH10: 163.77164 | AI10: 159.73189 | AJ10: 157.89429 | AK10: 150.94703 | AL10: 145.18982 | AM10: 148.30629 | AN10: 144.99016 | AO10: 144.25848 | AP10: 144.00911 | AQ10: 139.61977 | AR10: 140.65041 | AS10: 140.96235 | AT10: 138.33303 | AU10: 134.9404 | AV10: 136.66968 | AW10: 133.30689 | AX10: 131.26903 | AY10: 131.01016 | AZ10: 133.07738 | BA10: 134.11195 | BB10: 135.63627 | BC10: 137.51608 | BD10: 138.7897 | BE10: 147.75928 | BF10: 150.66325 | BG10: 149.67779 | BH10: 146.60735 | BI10: 143.13853 | BJ10: 138.26274 | BK10: 138.31798 | BL10: 138.03675 | BM10: 137.07232 | BN10: 139.43213 | BO10: 139.91987 | BP10: 139.82902 | BQ10: 139.66192 | BR10: 138.72328 | BS10: 139.00423 | BT10: 139.153 | BU10: 136.34444 | BV10: 136.90745 | BW10: 139.04175 | BX10: 141.35285 | BY10: 142.52613 | BZ10: 146.11678 | CA10: 149.4142 | CB10: 144.67362 | CC10: 148.43797 | CD10: 145.50082 | CE10: 145.53242 | CF10: 144.1459 | CG10: 141.27311 | CH10: 139.34979 | CI10: 136.7083 | CJ10: 136.08383 | CK10: 136.02252 | CL10: 137.38096 | CM10: 136.56089 | CN10: 139.53883 | CO10: 136.93275 | CP10: 134.43032 | CQ10: 134.54915 | CR10: 131.91753 | CS10: 133.31502 | CT10: 131.24024 | CU10: 130.97441 | CV10: 133.529 | CW10: 136.1545 | CX10: 139.99281 | CY10: 139.9439 | CZ10: 137.68733 | DA10: 138.84958 | DB10: 135.63491 | DC10: 135.56698 | DD10: 134.19043 | DE10: 131.63911 | DF10: 125.39281 | DG10: 126.05815 | DH10: 123.76682 | DI10: 124.34706 | DJ10: 124.7783 | DK10: 119.83457 | DL10: 126.0636 | DM10: 120.57718 | DN10: 112.01989 | DO10: 98.076277 | DP10: 99.242305 | DQ10: 99.554972 | DR10: 96.705057 | DS10: 98.911012 | DT10: 97.968775 | DU10: 96.404118 | DV10: 99.795133 | DW10: 100.2915 | DX10: 99.330788 | DY10: 98.549104 | DZ10: 87.366575 | EA10: 86.929389 | EB10: 100.97221 | EC10: 105.76266 | ED10: 112.22641 | EE10: 116.29065 | EF10: 116.47204 | EG10: 118.70968 | EH10: 126.78725 | EI10: 132.46495 | EJ10: 139.83357 | EK10: 151.28614 | EL10: 151.74035 | EM10: 155.49458 | EN10: 148.28083 | EO10: 138.7824 | EP10: 135.30749 | EQ10: 118.80883 | ER10: 108.66681 | ES10: 108.35053 | ET10: 110.63473 | EU10: 111.32415 | EV10: 112.1128 | EW10: 114.04322 | EX10: 112.27395 | EY10: 113.78469 | EZ10: 116.32788 | FA10: 118.76628 | FB10: 120.78972 | FC10: 120.1602 | FD10: 120.5714 | FE10: 119.37667 | FF10: 128.8709 | FG10: 126.76561 | FH10: 130.25016 | FI10: 131.09007 | FJ10: 127.46978 | FK10: 127.23451 | FL10: 125.81004 | FM10: 127.04044 | FN10: 127.84899 | FO10: 126.22638 | FP10: 124.13972 | FQ10: 123.32209 | FR10: 121.76794 | FS10: 127.87901 | FT10: 129.5287 | FU10: 140.97879 | FV10: 137.09144 | FW10: 183.04407 | FX10: 190.23332 | FY10: 167.3801 | FZ10: 160.19268 | GA10: 161.57018 | GB10: 162.9712 | GC10: 170.16977 | GD10: 172.01026 | GE10: 180.89559 | GF10: 173.34064 | GG10: 165.80627 | GH10: 162.84002 | GI10: 153.78276 | GJ10: 147.42528 | GK10: 141.13974 | GL10: 129.28881 | GM10: 118.87431 | GN10: 114.65894 | GO10: 108.05924 | GP10: 101.91645 | GQ10: 100.93839 | GR10: 97.223239 | GS10: 93.257916 | GT10: 89.203483 | GU10: 90.007191
A11: (Cartera irregular - Previsiones) / Financiaciones | B11: 10.108446 | C11: 7.0189256 | D11: 0.57508928 | E11: -1.1294786 | F11: -0.3389841 | G11: -0.46794653 | H11: -0.50886956 | I11: -0.40775348 | J11: -0.41926639 | K11: -0.49231158 | L11: -0.52113851 | M11: -0.56355651 | N11: -0.53956049 | O11: -0.6028273 | P11: -0.6247908 | Q11: -0.72500322 | R11: -0.77711505 | S11: -0.81296873 | T11: -0.84099512 | U11: -0.90566203 | V11: -0.92615514 | W11: -0.97146882 | X11: -0.98613041 | Y11: -1.0044309 | Z11: -0.98561876 | AA11: -0.92221418 | AB11: -0.95780288 | AC11: -0.98701409 | AD11: -0.99002014 | AE11: -1.0158649 | AF11: -0.99817503 | AG11: -0.99310722 | AH11: -0.93923684 | AI11: -0.90590411 | AJ11: -0.89715239 | AK11: -0.83373484 | AL11: -0.7778267 | AM11: -0.80302147 | AN11: -0.7721462 | AO11: -0.76752393 | AP11: -0.75648688 | AQ11: -0.70315474 | AR11: -0.71019674 | AS11: -0.71051197 | AT11: -0.68436057 | AU11: -0.64697082 | AV11: -0.66709675 | AW11: -0.62758037 | AX11: -0.59980668 | AY11: -0.59251728 | AZ11: -0.62778264 | BA11: -0.64073056 | BB11: -0.64985337 | BC11: -0.67435739 | BD11: -0.6820292 | BE11: -0.82746882 | BF11: -0.89175112 | BG11: -0.89521308 | BH11: -0.86393882 | BI11: -0.8274708 | BJ11: -0.77958012 | BK11: -0.77239588 | BL11: -0.77360248 | BM11: -0.7740008 | BN11: -0.79928847 | BO11: -0.81211407 | BP11: -0.80798533 | BQ11: -0.78929774 | BR11: -0.77996728 | BS11: -0.77999549 | BT11: -0.77995356 | BU11: -0.74790205 | BV11: -0.75047316 | BW11: -0.76000982 | BX11: -0.78084524 | BY11: -0.7802379 | BZ11: -0.81412804 | CA11: -0.83329007 | CB11: -0.77237629 | CC11: -0.84129086 | CD11: -0.81103171 | CE11: -0.82539072 | CF11: -0.80958613 | CG11: -0.76749625 | CH11: -0.74065118 | CI11: -0.701405 | CJ11: -0.69971108 | CK11: -0.6891324 | CL11: -0.69618023 | CM11: -0.68247322 | CN11: -0.71436004 | CO11: -0.67830899 | CP11: -0.65832831 | CQ11: -0.66266274 | CR11: -0.62200517 | CS11: -0.65816479 | CT11: -0.62920422 | CU11: -0.62694318 | CV11: -0.65700296 | CW11: -0.6900939 | CX11: -0.73916349 | CY11: -0.73797776 | CZ11: -0.71040381 | DA11: -0.71108861 | DB11: -0.67575817 | DC11: -0.68251179 | DD11: -0.67276658 | DE11: -0.63597548 | DF11: -0.54768174 | DG11: -0.55688608 | DH11: -0.53954871 | DI11: -0.54414294 | DJ11: -0.57261721 | DK11: -0.51614465 | DL11: -0.74328631 | DM11: -0.63965646 | DN11: -0.42491154 | DO11: 0.073890742 | DP11: 0.030566722 | DQ11: 0.018563726 | DR11: 0.14753342 | DS11: 0.049389994 | DT11: 0.094869041 | DU11: 0.16912215 | DV11: 0.009826835 | DW11: -0.01421202 | DX11: 0.033750862 | DY11: 0.083404631 | DZ11: 0.76128229 | EA11: 0.80483071 | EB11: -0.051429257 | EC11: -0.29977649 | ED11: -0.63141815 | EE11: -0.81064863 | EF11: -0.82547424 | EG11: -0.89687515 | EH11: -1.2109657 | EI11: -1.3776872 | EJ11: -1.643259 | EK11: -1.98029 | EL11: -1.9905748 | EM11: -2.0877203 | EN11: -1.8686639 | EO11: -1.6146116 | EP11: -1.506195 | EQ11: -0.91460591 | ER11: -0.46965552 | ES11: -0.44454986 | ET11: -0.53582675 | EU11: -0.55432326 | EV11: -0.55553747 | EW11: -0.60742046 | EX11: -0.53221506 | EY11: -0.57829027 | EZ11: -0.63632925 | FA11: -0.66885159 | FB11: -0.70045473 | FC11: -0.650548 | FD11: -0.64317904 | FE11: -0.60810438 | FF11: -0.89656805 | FG11: -0.82666548 | FH11: -0.91785296 | FI11: -0.97462261 | FJ11: -0.88137231 | FK11: -0.86877319 | FL11: -0.82307781 | FM11: -0.8299286 | FN11: -0.84661324 | FO11: -0.79859789 | FP11: -0.73889073 | FQ11: -0.73507606 | FR11: -0.6577079 | FS11: -0.78489438 | FT11: -0.78390286 | FU11: -1.4975421 | FV11: -1.3031489 | FW11: -1.589554 | FX11: -1.6817188 | FY11: -1.2393793 | FZ11: -1.1079434 | GA11: -1.090673 | GB11: -1.0567825 | GC11: -1.126136 | GD11: -1.1322677 | GE11: -1.2087935 | GF11: -1.1040168 | GG11: -1.0153671 | GH11: -1.024496 | GI11: -0.95374327 | GJ11: -0.93229689 | GK11: -0.90021008 | GL11: -0.7558299 | GM11: -0.54913936 | GN11: -0.46720126 | GO11: -0.29995012 | GP11: -0.079649402 | GQ11: -0.042674985 | GR11: 0.14510394 | GS11: 0.37394253 | GT11: 0.68565224 | GU11: 0.6701627
A12: (Cartera irregular - Previsiones) / PN | B12: 16.634448 | C12: 11.53376 | D12: 1.0641854 | E12: -2.4893468 | F12: -0.84209778 | G12: -1.4714229 | H12: -1.711562 | I12: -1.2731333 | J12: -1.2937752 | K12: -1.5010794 | L12: -1.5975861 | M12: -1.8177849 | N12: -1.8136579 | O12: -2.0324217 | P12: -2.0883288 | Q12: -2.4424971 | R12: -2.6593351 | S12: -2.8038148 | T12: -2.9386097 | U12: -3.2476264 | V12: -3.3178174 | W12: -3.5285993 | X12: -3.7124945 | Y12: -3.8957328 | Z12: -3.8959782 | AA12: -3.7238968 | AB12: -3.9444238 | AC12: -4.1295671 | AD12: -4.2672066 | AE12: -4.3802008 | AF12: -4.3100521 | AG12: -4.2597234 | AH12: -3.9914072 | AI12: -3.8265913 | AJ12: -3.7559373 | AK12: -3.4767493 | AL12: -3.238211 | AM12: -3.3580377 | AN12: -3.2026893 | AO12: -3.2025232 | AP12: -3.1421667 | AQ12: -2.9496763 | AR12: -3.0078872 | AS12: -3.0921232 | AT12: -2.9371292 | AU12: -2.7381949 | AV12: -2.8156949 | AW12: -2.6521047 | AX12: -2.5334219 | AY12: -2.543465 | AZ12: -2.6679708 | BA12: -2.7328059 | BB12: -2.776007 | BC12: -2.8624914 | BD12: -2.8956678 | BE12: -3.5182176 | BF12: -3.5840596 | BG12: -3.5154309 | BH12: -3.3422396 | BI12: -3.17565 | BJ12: -2.9344319 | BK12: -2.9154019 | BL12: -2.8683006 | BM12: -2.8319051 | BN12: -2.9212832 | BO12: -2.9632294 | BP12: -2.9538301 | BQ12: -2.9205903 | BR12: -2.818579 | BS12: -2.8013157 | BT12: -2.7899365 | BU12: -2.704619 | BV12: -2.7320537 | BW12: -2.8183146 | BX12: -2.8836291 | BY12: -2.8994552 | BZ12: -3.0083858 | CA12: -3.105416 | CB12: -2.9160567 | CC12: -3.1590618 | CD12: -2.9976295 | CE12: -2.9594059 | CF12: -2.8439076 | CG12: -2.7353547 | CH12: -2.6193284 | CI12: -2.4634127 | CJ12: -2.4352746 | CK12: -2.5019169 | CL12: -2.5402182 | CM12: -2.512293 | CN12: -2.6748512 | CO12: -2.5378219 | CP12: -2.4552624 | CQ12: -2.4607643 | CR12: -2.3026719 | CS12: -2.4742917 | CT12: -2.3919197 | CU12: -2.3821062 | CV12: -2.5049748 | CW12: -2.6727328 | CX12: -2.9241901 | CY12: -2.9745002 | CZ12: -2.9074953 | DA12: -2.9939978 | DB12: -2.5708985 | DC12: -2.5943959 | DD12: -2.640776 | DE12: -2.547 | DF12: -2.2730758 | DG12: -2.3325043 | DH12: -2.2336634 | DI12: -2.3589492 | DJ12: -2.4219083 | DK12: -2.0691953 | DL12: -3.020434 | DM12: -2.4400031 | DN12: -1.5622465 | DO12: 0.2657395 | DP12: 0.11203664 | DQ12: 0.069379083 | DR12: 0.544759 | DS12: 0.17569493 | DT12: 0.32825812 | DU12: 0.63823773 | DV12: 0.034025696 | DW12: -0.048432775 | DX12: 0.1113224 | DY12: 0.2625902 | DZ12: 1.8789586 | EA12: 1.9617781 | EB12: -0.12560312 | EC12: -0.74050843 | ED12: -1.5311351 | EE12: -1.9526105 | EF12: -1.9543288 | EG12: -2.063167 | EH12: -2.7519157 | EI12: -3.129523 | EJ12: -3.7063377 | EK12: -4.4329799 | EL12: -4.2930816 | EM12: -4.4073286 | EN12: -3.8525448 | EO12: -3.2831899 | EP12: -3.0239343 | EQ12: -1.8266006 | ER12: -0.9222044 | ES12: -0.86619794 | ET12: -1.0421597 | EU12: -1.0853921 | EV12: -1.103271 | EW12: -1.207957 | EX12: -1.0258371 | EY12: -1.0969676 | EZ12: -1.1797018 | FA12: -1.2197196 | FB12: -1.2756629 | FC12: -1.1986292 | FD12: -1.145318 | FE12: -1.0409048 | FF12: -1.4638344 | FG12: -1.328278 | FH12: -1.4624294 | FI12: -1.510424 | FJ12: -1.3246289 | FK12: -1.2780292 | FL12: -1.2195196 | FM12: -1.2807061 | FN12: -1.2855279 | FO12: -1.190817 | FP12: -1.0812036 | FQ12: -1.0467935 | FR12: -0.89471679 | FS12: -1.0427271 | FT12: -0.96303636 | FU12: -1.5655692 | FV12: -1.2507503 | FW12: -1.4323723 | FX12: -1.472784 | FY12: -1.0619784 | FZ12: -1.0613653 | GA12: -1.127361 | GB12: -1.1686421 | GC12: -1.3108303 | GD12: -1.4043207 | GE12: -1.6115834 | GF12: -1.5382149 | GG12: -1.52392 | GH12: -1.5618558 | GI12: -1.5134209 | GJ12: -1.5487473 | GK12: -1.5405566 | GL12: -1.3463125 | GM12: -1.0437008 | GN12: -0.92628956 | GO12: -0.61590891 | GP12: -0.16871903 | GQ12: -0.087036555 | GR12: 0.2970586 | GS12: 0.77196596 | GT12: 1.387712 | GU12: 1.329267
A13: Fuente: BCRA
A18: Bancos privados
A19: En porcentaje | B19: 37591 | C19: 37956 | D19: 38322 | E19: 38687 | F19: 39052 | G19: 39417 | H19: 39783 | I19: 40148 | J19: 40179 | K19: 40210 | L19: 40238 | M19: 40269 | N19: 40299 | O19: 40330 | P19: 40360 | Q19: 40391 | R19: 40422 | S19: 40452 | T19: 40483 | U19: 40513 | V19: 40544 | W19: 40575 | X19: 40603 | Y19: 40634 | Z19: 40664 | AA19: 40695 | AB19: 40725 | AC19: 40756 | AD19: 40787 | AE19: 40817 | AF19: 40848 | AG19: 40878 | AH19: 40909 | AI19: 40940 | AJ19: 40969 | AK19: 41000 | AL19: 41030 | AM19: 41061 | AN19: 41091 | AO19: 41122 | AP19: 41153 | AQ19: 41183 | AR19: 41214 | AS19: 41244 | AT19: 41275 | AU19: 41306 | AV19: 41334 | AW19: 41365 | AX19: 41395 | AY19: 41426 | AZ19: 41456 | BA19: 41487 | BB19: 41518 | BC19: 41548 | BD19: 41579 | BE19: 41609 | BF19: 41640 | BG19: 41671 | BH19: 41699 | BI19: 41730 | BJ19: 41760 | BK19: 41791 | BL19: 41821 | BM19: 41852 | BN19: 41883 | BO19: 41913 | BP19: 41944 | BQ19: 41974 | BR19: 42005 | BS19: 42036 | BT19: 42064 | BU19: 42095 | BV19: 42125 | BW19: 42156 | BX19: 42186 | BY19: 42217 | BZ19: 42248 | CA19: 42278 | CB19: 42309 | CC19: 42339 | CD19: 42370 | CE19: 42401 | CF19: 42430 | CG19: 42461 | CH19: 42491 | CI19: 42522 | CJ19: 42552 | CK19: 42583 | CL19: 42614 | CM19: 42644 | CN19: 42675 | CO19: 42705 | CP19: 42736 | CQ19: 42767 | CR19: 42795 | CS19: 42826 | CT19: 42856 | CU19: 42887 | CV19: 42917 | CW19: 42948 | CX19: 42979 | CY19: 43009 | CZ19: 43040 | DA19: 43070 | DB19: 43101 | DC19: 43132 | DD19: 43160 | DE19: 43191 | DF19: 43221 | DG19: 43252 | DH19: 43282 | DI19: 43313 | DJ19: 43344 | DK19: 43374 | DL19: 43405 | DM19: 43435 | DN19: 43466 | DO19: 43497 | DP19: 43525 | DQ19: 43556 | DR19: 43586 | DS19: 43617 | DT19: 43647 | DU19: 43678 | DV19: 43709 | DW19: 43739 | DX19: 43770 | DY19: 43800 | DZ19: 43831 | EA19: 43862 | EB19: 43891 | EC19: 43922 | ED19: 43952 | EE19: 43983 | EF19: 44013 | EG19: 44044 | EH19: 44075 | EI19: 44105 | EJ19: 44136 | EK19: 44166 | EL19: 44197 | EM19: 44228 | EN19: 44256 | EO19: 44287 | EP19: 44317 | EQ19: 44348 | ER19: 44378 | ES19: 44409 | ET19: 44440 | EU19: 44470 | EV19: 44501 | EW19: 44531 | EX19: 44562 | EY19: 44593 | EZ19: 44621 | FA19: 44652 | FB19: 44682 | FC19: 44713 | FD19: 44743 | FE19: 44774 | FF19: 44805 | FG19: 44835 | FH19: 44866 | FI19: 44896 | FJ19: 44927 | FK19: 44958 | FL19: 44986 | FM19: 45017 | FN19: 45047 | FO19: 45078 | FP19: 45108 | FQ19: 45139 | FR19: 45170 | FS19: 45200 | FT19: 45231 | FU19: 45261 | FV19: 45292 | FW19: 45323 | FX19: 45352 | FY19: 45383 | FZ19: 45413 | GA19: 45444 | GB19: 45474 | GC19: 45505 | GD19: 45536 | GE19: 45566 | GF19: 45597 | GG19: 45627 | GH19: 45658 | GI19: 45689 | GJ19: 45717 | GK19: 45748 | GL19: 45778 | GM19: 45809 | GN19: 45839 | GO19: 45870 | GP19: 45901 | GQ19: 45931 | GR19: 45962 | GS19: 45992 | GT19: 46023 | GU19: 46054
A20: Cartera irregular total | B20: 19.800766 | C20: 15.70533 | D20: 8.8706643 | E20: 4.4307483 | F20: 2.9167146 | G20: 2.2025977 | H20: 2.5301599 | I20: 3.0927384 | J20: 3.1738511 | K20: 3.1020812 | L20: 2.9538762 | M20: 2.8204168 | N20: 2.7202349 | O20: 2.6261991 | P20: 2.588311 | Q20: 2.5043414 | R20: 2.2801886 | S20: 2.2053333 | T20: 2.0842876 | U20: 1.9074514 | V20: 1.807094 | W20: 1.7508555 | X20: 1.6642421 | Y20: 1.6169071 | Z20: 1.5799472 | AA20: 1.5178769 | AB20: 1.4502558 | AC20: 1.4148043 | AD20: 1.3224862 | AE20: 1.3251476 | AF20: 1.3073411 | AG20: 1.3332553 | AH20: 1.4236265 | AI20: 1.4873077 | AJ20: 1.5122605 | AK20: 1.6256052 | AL20: 1.7215818 | AM20: 1.6278712 | AN20: 1.6930727 | AO20: 1.7325294 | AP20: 1.6699798 | AQ20: 1.755611 | AR20: 1.7221305 | AS20: 1.7080054 | AT20: 1.7884589 | AU20: 1.8735504 | AV20: 1.8091671 | AW20: 1.8566453 | AX20: 1.8977721 | AY20: 1.886866 | AZ20: 1.8955634 | BA20: 1.8886275 | BB20: 1.8215028 | BC20: 1.8029236 | BD20: 1.7401956 | BE20: 1.6369839 | BF20: 1.6830225 | BG20: 1.7568438 | BH20: 1.7925409 | BI20: 1.8762533 | BJ20: 1.9936861 | BK20: 1.9546532 | BL20: 1.9460999 | BM20: 2.0087139 | BN20: 1.9383547 | BO20: 1.9633765 | BP20: 1.9686875 | BQ20: 1.853791 | BR20: 1.8817273 | BS20: 1.8601897 | BT20: 1.8454521 | BU20: 1.9229652 | BV20: 1.8856158 | BW20: 1.7687556 | BX20: 1.7334064 | BY20: 1.6708413 | BZ20: 1.6339986 | CA20: 1.56768 | CB20: 1.5425604 | CC20: 1.485105 | CD20: 1.5303095 | CE20: 1.5479501 | CF20: 1.5451247 | CG20: 1.5852847 | CH20: 1.5997731 | CI20: 1.6093658 | CJ20: 1.6094871 | CK20: 1.6301997 | CL20: 1.5760346 | CM20: 1.5979629 | CN20: 1.5601704 | CO20: 1.5080251 | CP20: 1.5969689 | CQ20: 1.6610633 | CR20: 1.7027313 | CS20: 1.7816063 | CT20: 1.800751 | CU20: 1.814342 | CV20: 1.7456136 | CW20: 1.71402 | CX20: 1.6691125 | CY20: 1.7035114 | CZ20: 1.7576801 | DA20: 1.7166548 | DB20: 1.8073982 | DC20: 1.8432753 | DD20: 1.9312842 | DE20: 1.9492752 | DF20: 2.0827037 | DG20: 2.0574106 | DH20: 2.2340174 | DI20: 2.1756702 | DJ20: 2.2648176 | DK20: 2.7041809 | DL20: 2.9569647 | DM20: 3.0245732 | DN20: 3.3827182 | DO20: 3.6994372 | DP20: 3.8395135 | DQ20: 3.9518682 | DR20: 4.1418993 | DS20: 4.1878882 | DT20: 4.2923843 | DU20: 4.2208759 | DV20: 4.2514444 | DW20: 4.2827416 | DX20: 4.4874638 | DY20: 4.3115847 | DZ20: 4.6264977 | EA20: 4.7448273 | EB20: 3.7715623 | EC20: 3.622657 | ED20: 3.571831 | EE20: 3.2477866 | EF20: 3.1677877 | EG20: 2.9326878 | EH20: 2.7040148 | EI20: 2.4479526 | EJ20: 2.3483201 | EK20: 2.1786372 | EL20: 2.125663 | EM20: 2.0379657 | EN20: 2.2254916 | EO20: 2.6230938 | EP20: 2.7794053 | EQ20: 3.1840411 | ER20: 3.7114563 | ES20: 3.6524709 | ET20: 3.3906951 | EU20: 3.2639234 | EV20: 2.9835603 | EW20: 2.76103 | EX20: 2.7988598 | EY20: 2.6883978 | EZ20: 2.3841468 | FA20: 2.1906862 | FB20: 1.9854994 | FC20: 1.8425227 | FD20: 1.7440293 | FE20: 1.7285594 | FF20: 1.6943616 | FG20: 1.7102555 | FH20: 1.6827499 | FI20: 1.7605935 | FJ20: 1.8471079 | FK20: 1.8310158 | FL20: 1.8714771 | FM20: 1.8138808 | FN20: 1.7845041 | FO20: 1.7428663 | FP20: 1.7915985 | FQ20: 1.7221326 | FR20: 1.6892004 | FS20: 1.6088791 | FT20: 1.5265913 | FU20: 1.5448219 | FV20: 1.503632 | FW20: 1.4277124 | FX20: 1.3940211 | FY20: 1.4042004 | FZ20: 1.4686032 | GA20: 1.4110553 | GB20: 1.4286428 | GC20: 1.4192137 | GD20: 1.4166821 | GE20: 1.3582005 | GF20: 1.3620323 | GG20: 1.4909082 | GH20: 1.5947045 | GI20: 1.7541036 | GJ20: 1.9395867 | GK20: 2.1749846 | GL20: 2.5422819 | GM20: 2.8979518 | GN20: 3.1765856 | GO20: 3.7741098 | GP20: 4.1238194 | GQ20: 4.4727158 | GR20: 5.1109467 | GS20: 5.2835929 | GT20: 6.0622371 | GU20: 6.5198641
A21: Previsiones / Cartera irregular | B21: 71.261521 | C21: 73.047582 | D21: 89.231906 | E21: 102.68403 | F21: 114.17863 | G21: 123.38365 | H21: 118.5399 | I21: 115.90954 | J21: 114.74935 | K21: 116.4322 | L21: 117.93875 | M21: 119.8608 | N21: 120.89489 | O21: 122.35057 | P21: 123.58846 | Q21: 125.26338 | R21: 130.21808 | S21: 131.93552 | T21: 135.42119 | U21: 143.51961 | V21: 147.39811 | W21: 150.03808 | X21: 153.51516 | Y21: 156.51626 | Z21: 156.81266 | AA21: 154.92154 | AB21: 160.93094 | AC21: 164.95454 | AD21: 169.29361 | AE21: 171.52135 | AF21: 170.98686 | AG21: 168.27855 | AH21: 160.73847 | AI21: 155.08759 | AJ21: 154.54676 | AK21: 145.9736 | AL21: 140.54754 | AM21: 146.33198 | AN21: 142.84965 | AO21: 141.58311 | AP21: 144.56353 | AQ21: 138.71789 | AR21: 139.82809 | AS21: 140.01251 | AT21: 136.54971 | AU21: 132.08211 | AV21: 135.20045 | AW21: 133.58743 | AX21: 130.57527 | AY21: 130.14327 | AZ21: 132.01384 | BA21: 132.47502 | BB21: 134.37611 | BC21: 135.42574 | BD21: 138.03936 | BE21: 145.97725 | BF21: 149.22239 | BG21: 145.79653 | BH21: 143.68559 | BI21: 139.81506 | BJ21: 135.56904 | BK21: 135.786 | BL21: 137.60701 | BM21: 136.8085 | BN21: 138.9552 | BO21: 139.03655 | BP21: 138.44682 | BQ21: 141.55572 | BR21: 140.66616 | BS21: 141.30371 | BT21: 141.61938 | BU21: 138.56787 | BV21: 139.10489 | BW21: 143.32612 | BX21: 145.34188 | BY21: 145.79273 | BZ21: 149.48687 | CA21: 153.03357 | CB21: 152.93594 | CC21: 156.39974 | CD21: 153.72456 | CE21: 153.07591 | CF21: 151.78427 | CG21: 147.08614 | CH21: 145.62337 | CI21: 143.58308 | CJ21: 144.61332 | CK21: 145.1998 | CL21: 146.55371 | CM21: 144.86359 | CN21: 146.11616 | CO21: 145.01538 | CP21: 140.91191 | CQ21: 138.42727 | CR21: 134.28664 | CS21: 133.48913 | CT21: 131.81714 | CU21: 130.61426 | CV21: 133.10221 | CW21: 135.03668 | CX21: 138.31177 | CY21: 136.54388 | CZ21: 133.25602 | DA21: 132.37517 | DB21: 128.4684 | DC21: 127.49021 | DD21: 125.03324 | DE21: 123.39414 | DF21: 118.74089 | DG21: 119.25439 | DH21: 116.51069 | DI21: 118.7933 | DJ21: 119.60984 | DK21: 111.47029 | DL21: 105.04396 | DM21: 105.58002 | DN21: 102.73387 | DO21: 100.08408 | DP21: 102.50939 | DQ21: 102.8613 | DR21: 104.56277 | DS21: 107.37346 | DT21: 107.17185 | DU21: 105.60246 | DV21: 110.6218 | DW21: 113.0048 | DX21: 111.665 | DY21: 117.20888 | DZ21: 105.54707 | EA21: 104.4477 | EB21: 128.1244 | EC21: 136.51098 | ED21: 147.60787 | EE21: 157.94882 | EF21: 165.22711 | EG21: 173.77117 | EH21: 190.95721 | EI21: 205.76555 | EJ21: 211.50486 | EK21: 239.02028 | EL21: 244.19297 | EM21: 251.98362 | EN21: 223.71643 | EO21: 191.98385 | EP21: 180.67111 | EQ21: 156.8805 | ER21: 136.95245 | ES21: 136.01781 | ET21: 141.82747 | EU21: 144.50121 | EV21: 146.92035 | EW21: 151.67679 | EX21: 146.26594 | EY21: 148.78117 | EZ21: 157.16286 | FA21: 162.84774 | FB21: 169.68388 | FC21: 169.75859 | FD21: 173.14964 | FE21: 173.92757 | FF21: 180.2214 | FG21: 170.95021 | FH21: 180.62744 | FI21: 179.28201 | FJ21: 169.19723 | FK21: 170.25532 | FL21: 166.45465 | FM21: 166.91811 | FN21: 167.67368 | FO21: 168.86267 | FP21: 162.00058 | FQ21: 167.00502 | FR21: 162.26269 | FS21: 173.03344 | FT21: 179.20746 | FU21: 185.25023 | FV21: 181.7432 | FW21: 189.12343 | FX21: 186.43626 | FY21: 188.36921 | FZ21: 171.26515 | GA21: 173.2499 | GB21: 171.02425 | GC21: 177.97204 | GD21: 178.26177 | GE21: 187.71262 | GF21: 196.31315 | GG21: 178.11725 | GH21: 175.015 | GI21: 162.98308 | GJ21: 156.69963 | GK21: 148.90254 | GL21: 136.69414 | GM21: 122.84868 | GN21: 118.91193 | GO21: 110.74695 | GP21: 105.27837 | GQ21: 104.31245 | GR21: 98.301166 | GS21: 95.700571 | GT21: 91.156531 | GU21: 90.968045
A22: (Cartera irregular - Previsiones) / Financiaciones | B22: 5.6904391 | C22: 4.2329662 | D22: 0.95520146 | E22: -0.1189226 | F22: -0.41355019 | G22: -0.51504763 | H22: -0.46908903 | I22: -0.49204051 | J22: -0.46812244 | K22: -0.50974017 | L22: -0.52988857 | M22: -0.56015734 | N22: -0.56838998 | O22: -0.58697034 | P22: -0.61054274 | Q22: -0.63268127 | R22: -0.68902918 | S22: -0.70428475 | T22: -0.73827956 | U22: -0.83011538 | V22: -0.85652839 | W22: -0.87609457 | X22: -0.89062181 | Y22: -0.91381549 | Z22: -0.89761001 | AA22: -0.83364129 | AB22: -0.88365457 | AC22: -0.9189797 | AD22: -0.91639836 | AE22: -0.94776345 | AF22: -0.92804033 | AG22: -0.91032733 | AH22: -0.86468897 | AI22: -0.8193219 | AJ22: -0.82488916 | AK22: -0.74734925 | AL22: -0.6980591 | AM22: -0.75422501 | AN22: -0.72547581 | AO22: -0.72043969 | AP22: -0.74420201 | AQ22: -0.67973547 | AR22: -0.6858917 | AS22: -0.68341584 | AT22: -0.65367653 | AU22: -0.60107443 | AV22: -0.63683497 | AW22: -0.62359944 | AX22: -0.58024892 | AY22: -0.56876314 | AZ22: -0.60684259 | BA22: -0.61333218 | BB22: -0.62616187 | BC22: -0.6386991 | BD22: -0.66195932 | BE22: -0.75264015 | BF22: -0.82842398 | BG22: -0.80457353 | BH22: -0.78308205 | BI22: -0.74703145 | BJ22: -0.70913506 | BK22: -0.69949209 | BL22: -0.73187004 | BM22: -0.73937738 | BN22: -0.75508993 | BO22: -0.76643437 | BP22: -0.75689776 | BQ22: -0.77035614 | BR22: -0.76522626 | BS22: -0.76832729 | BT22: -0.76806574 | BU22: -0.74164666 | BV22: -0.73736798 | BW22: -0.76633317 | BX22: -0.78595901 | BY22: -0.76512389 | BZ22: -0.80861479 | CA22: -0.83139668 | CB22: -0.81656884 | CC22: -0.83759532 | CD22: -0.82215197 | CE22: -0.82158858 | CF22: -0.80013156 | CG22: -0.7464494 | CH22: -0.72987035 | CI22: -0.70141121 | CJ22: -0.71804567 | CK22: -0.73684707 | CL22: -0.73370266 | CM22: -0.71690351 | CN22: -0.71949068 | CO22: -0.67884319 | CP22: -0.65335044 | CQ22: -0.63830124 | CR22: -0.58380945 | CS22: -0.59664442 | CT22: -0.57294747 | CU22: -0.55544731 | CV22: -0.57783675 | CW22: -0.60053567 | CX22: -0.63946654 | CY22: -0.62252916 | CZ22: -0.58453445 | DA22: -0.55576999 | DB22: -0.51453737 | DC22: -0.50672032 | DD22: -0.483463 | DE22: -0.45601612 | DF22: -0.39031711 | DG22: -0.39614181 | DH22: -0.3688518 | DI22: -0.40888031 | DJ22: -0.44412706 | DK22: -0.3101775 | DL22: -0.14914813 | DM22: -0.16877178 | DN22: -0.092479185 | DO22: -0.0031105338 | DP22: -0.096348506 | DQ22: -0.11307468 | DR22: -0.18898513 | DS22: -0.30879242 | DT22: -0.30784324 | DU22: -0.23647301 | DV22: -0.45158006 | DW22: -0.55696186 | DX22: -0.52346283 | DY22: -0.74197532 | DZ22: -0.25663493 | EA22: -0.21103546 | EB22: -1.0607293 | EC22: -1.3226675 | ED22: -1.7004726 | EE22: -1.8820542 | EF22: -2.0662564 | EG22: -2.1634782 | EH22: -2.4594964 | EI22: -2.5890906 | EJ22: -2.6184911 | EK22: -3.0287477 | EL22: -3.0650566 | EM22: -3.097374 | EN22: -2.7532988 | EO22: -2.4128227 | EP22: -2.2421771 | EQ22: -1.8110986 | ER22: -1.3714739 | ES22: -1.3155401 | ET22: -1.418242 | EU22: -1.4524855 | EV22: -1.3998969 | EW22: -1.4268116 | EX22: -1.2949188 | EY22: -1.311432 | EZ22: -1.3628466 | FA22: -1.3767969 | FB22: -1.383573 | FC22: -1.2853179 | FD22: -1.2757512 | FE22: -1.277882 | FF22: -1.3592406 | FG22: -1.2134299 | FH22: -1.3567581 | FI22: -1.395834 | FJ22: -1.2781474 | FK22: -1.2863859 | FL22: -1.2436836 | FM22: -1.2138147 | FN22: -1.2076396 | FO22: -1.2001842 | FP22: -1.1108015 | FQ22: -1.1539153 | FR22: -1.0517416 | FS22: -1.1750198 | FT22: -1.2091742 | FU22: -1.3169642 | FV22: -1.2291169 | FW22: -1.2724262 | FX22: -1.2049397 | FY22: -1.2408807 | FZ22: -1.0466022 | GA22: -1.0335965 | GB22: -1.0146829 | GC22: -1.1065899 | GD22: -1.1087205 | GE22: -1.1913133 | GF22: -1.3118162 | GG22: -1.1646565 | GH22: -1.1962676 | GI22: -1.1047884 | GJ22: -1.0997384 | GK22: -1.0636226 | GL22: -0.93286852 | GM22: -0.66214369 | GN22: -0.60075378 | GO22: -0.40560181 | GP22: -0.21767051 | GQ22: -0.19288376 | GR22: 0.086826501 | GS22: 0.22716435 | GT22: 0.53611207 | GU22: 0.58887117
